14:37:59 : ****************************** 
14:37:59 : Error occured Failed to run torchsummary. See above stack traces for more details. Executed layers up to: [] 
14:37:59 : Traceback (most recent call last):
  File "C:\Binson\Apps\Lib\site-packages\torchsummary\torchsummary.py", line 140, in summary
    _ = model.to(device)(*x, *args, **kwargs)  # type: ignore[misc]
        ^^^^^^^^^^^^^^^^^^^^^^^^^^^^^^^^^^^^^
  File "C:\Binson\Apps\Lib\site-packages\torch\nn\modules\module.py", line 1518, in _wrapped_call_impl
    return self._call_impl(*args, **kwargs)
           ^^^^^^^^^^^^^^^^^^^^^^^^^^^^^^^^
  File "C:\Binson\Apps\Lib\site-packages\torch\nn\modules\module.py", line 1527, in _call_impl
    return forward_call(*args, **kwargs)
           ^^^^^^^^^^^^^^^^^^^^^^^^^^^^^
  File "c:\Binson\Cloud\OneDrive - University of Hertfordshire\ProjectWorkables\MscProjectRepo\smt_repo\testing model summary.py", line 36, in forward
    x = self.pool(F.relu(self.conv1(x)))
                         ^^^^^^^^^^^^^
  File "C:\Binson\Apps\Lib\site-packages\torch\nn\modules\module.py", line 1518, in _wrapped_call_impl
    return self._call_impl(*args, **kwargs)
           ^^^^^^^^^^^^^^^^^^^^^^^^^^^^^^^^
  File "C:\Binson\Apps\Lib\site-packages\torch\nn\modules\module.py", line 1568, in _call_impl
    result = forward_call(*args, **kwargs)
             ^^^^^^^^^^^^^^^^^^^^^^^^^^^^^
  File "C:\Binson\Apps\Lib\site-packages\torch\nn\modules\conv.py", line 610, in forward
    return self._conv_forward(input, self.weight, self.bias)
           ^^^^^^^^^^^^^^^^^^^^^^^^^^^^^^^^^^^^^^^^^^^^^^^^^
  File "C:\Binson\Apps\Lib\site-packages\torch\nn\modules\conv.py", line 605, in _conv_forward
    return F.conv3d(
           ^^^^^^^^^
RuntimeError: Given groups=1, weight of size [128, 1, 3, 3, 3], expected input[1, 2, 1, 51, 38] to have 1 channels, but got 2 channels instead

The above exception was the direct cause of the following exception:

Traceback (most recent call last):
  File "c:\Binson\Cloud\OneDrive - University of Hertfordshire\ProjectWorkables\MscProjectRepo\smt_repo\testing model summary.py", line 260, in <module>
    summary(model,(1,51,38))
  File "C:\Binson\Apps\Lib\site-packages\torchsummary\torchsummary.py", line 143, in summary
    raise RuntimeError(
RuntimeError: Failed to run torchsummary. See above stack traces for more details. Executed layers up to: []
 
14:37:59 : ****************************** 
14:43:38 : ****************************** 
14:43:38 : Error occured Failed to run torchsummary. See above stack traces for more details. Executed layers up to: [] 
14:43:38 : Traceback (most recent call last):
  File "C:\Binson\Apps\Lib\site-packages\torchsummary\torchsummary.py", line 140, in summary
    _ = model.to(device)(*x, *args, **kwargs)  # type: ignore[misc]
        ^^^^^^^^^^^^^^^^^^^^^^^^^^^^^^^^^^^^^
  File "C:\Binson\Apps\Lib\site-packages\torch\nn\modules\module.py", line 1518, in _wrapped_call_impl
    return self._call_impl(*args, **kwargs)
           ^^^^^^^^^^^^^^^^^^^^^^^^^^^^^^^^
  File "C:\Binson\Apps\Lib\site-packages\torch\nn\modules\module.py", line 1527, in _call_impl
    return forward_call(*args, **kwargs)
           ^^^^^^^^^^^^^^^^^^^^^^^^^^^^^
  File "c:\Binson\Cloud\OneDrive - University of Hertfordshire\ProjectWorkables\MscProjectRepo\smt_repo\testing model summary.py", line 36, in forward
    x = self.pool(F.relu(self.conv1(x)))
                         ^^^^^^^^^^^^^
  File "C:\Binson\Apps\Lib\site-packages\torch\nn\modules\module.py", line 1518, in _wrapped_call_impl
    return self._call_impl(*args, **kwargs)
           ^^^^^^^^^^^^^^^^^^^^^^^^^^^^^^^^
  File "C:\Binson\Apps\Lib\site-packages\torch\nn\modules\module.py", line 1568, in _call_impl
    result = forward_call(*args, **kwargs)
             ^^^^^^^^^^^^^^^^^^^^^^^^^^^^^
  File "C:\Binson\Apps\Lib\site-packages\torch\nn\modules\conv.py", line 610, in forward
    return self._conv_forward(input, self.weight, self.bias)
           ^^^^^^^^^^^^^^^^^^^^^^^^^^^^^^^^^^^^^^^^^^^^^^^^^
  File "C:\Binson\Apps\Lib\site-packages\torch\nn\modules\conv.py", line 605, in _conv_forward
    return F.conv3d(
           ^^^^^^^^^
RuntimeError: Expected 4D (unbatched) or 5D (batched) input to conv3d, but got input of size: [2, 51, 38]

The above exception was the direct cause of the following exception:

Traceback (most recent call last):
  File "c:\Binson\Cloud\OneDrive - University of Hertfordshire\ProjectWorkables\MscProjectRepo\smt_repo\testing model summary.py", line 260, in <module>
    summary(model,(51,38))
  File "C:\Binson\Apps\Lib\site-packages\torchsummary\torchsummary.py", line 143, in summary
    raise RuntimeError(
RuntimeError: Failed to run torchsummary. See above stack traces for more details. Executed layers up to: []
 
14:43:38 : ****************************** 
14:49:01 : ****************************** 
14:49:01 : Error occured Failed to run torchsummary. See above stack traces for more details. Executed layers up to: [] 
14:49:01 : Traceback (most recent call last):
  File "C:\Binson\Apps\Lib\site-packages\torchsummary\torchsummary.py", line 140, in summary
    _ = model.to(device)(*x, *args, **kwargs)  # type: ignore[misc]
        ^^^^^^^^^^^^^^^^^^^^^^^^^^^^^^^^^^^^^
  File "C:\Binson\Apps\Lib\site-packages\torch\nn\modules\module.py", line 1518, in _wrapped_call_impl
    return self._call_impl(*args, **kwargs)
           ^^^^^^^^^^^^^^^^^^^^^^^^^^^^^^^^
  File "C:\Binson\Apps\Lib\site-packages\torch\nn\modules\module.py", line 1527, in _call_impl
    return forward_call(*args, **kwargs)
           ^^^^^^^^^^^^^^^^^^^^^^^^^^^^^
  File "c:\Binson\Cloud\OneDrive - University of Hertfordshire\ProjectWorkables\MscProjectRepo\smt_repo\testing model summary.py", line 36, in forward
    x = self.pool(F.relu(self.conv1(x)))
                         ^^^^^^^^^^^^^
  File "C:\Binson\Apps\Lib\site-packages\torch\nn\modules\module.py", line 1518, in _wrapped_call_impl
    return self._call_impl(*args, **kwargs)
           ^^^^^^^^^^^^^^^^^^^^^^^^^^^^^^^^
  File "C:\Binson\Apps\Lib\site-packages\torch\nn\modules\module.py", line 1568, in _call_impl
    result = forward_call(*args, **kwargs)
             ^^^^^^^^^^^^^^^^^^^^^^^^^^^^^
  File "C:\Binson\Apps\Lib\site-packages\torch\nn\modules\conv.py", line 610, in forward
    return self._conv_forward(input, self.weight, self.bias)
           ^^^^^^^^^^^^^^^^^^^^^^^^^^^^^^^^^^^^^^^^^^^^^^^^^
  File "C:\Binson\Apps\Lib\site-packages\torch\nn\modules\conv.py", line 605, in _conv_forward
    return F.conv3d(
           ^^^^^^^^^
RuntimeError: Expected 4D (unbatched) or 5D (batched) input to conv3d, but got input of size: [2, 38, 51]

The above exception was the direct cause of the following exception:

Traceback (most recent call last):
  File "c:\Binson\Cloud\OneDrive - University of Hertfordshire\ProjectWorkables\MscProjectRepo\smt_repo\testing model summary.py", line 260, in <module>
    summary(model,(38,51))
  File "C:\Binson\Apps\Lib\site-packages\torchsummary\torchsummary.py", line 143, in summary
    raise RuntimeError(
RuntimeError: Failed to run torchsummary. See above stack traces for more details. Executed layers up to: []
 
14:49:01 : ****************************** 
14:50:33 : ****************************** 
14:50:33 : Error occured Failed to run torchsummary. See above stack traces for more details. Executed layers up to: [] 
14:50:33 : Traceback (most recent call last):
  File "C:\Binson\Apps\Lib\site-packages\torchsummary\torchsummary.py", line 140, in summary
    _ = model.to(device)(*x, *args, **kwargs)  # type: ignore[misc]
        ^^^^^^^^^^^^^^^^^^^^^^^^^^^^^^^^^^^^^
  File "C:\Binson\Apps\Lib\site-packages\torch\nn\modules\module.py", line 1518, in _wrapped_call_impl
    return self._call_impl(*args, **kwargs)
           ^^^^^^^^^^^^^^^^^^^^^^^^^^^^^^^^
  File "C:\Binson\Apps\Lib\site-packages\torch\nn\modules\module.py", line 1527, in _call_impl
    return forward_call(*args, **kwargs)
           ^^^^^^^^^^^^^^^^^^^^^^^^^^^^^
  File "c:\Binson\Cloud\OneDrive - University of Hertfordshire\ProjectWorkables\MscProjectRepo\smt_repo\testing model summary.py", line 36, in forward
    x = self.pool(F.relu(self.conv1(x)))
                         ^^^^^^^^^^^^^
  File "C:\Binson\Apps\Lib\site-packages\torch\nn\modules\module.py", line 1518, in _wrapped_call_impl
    return self._call_impl(*args, **kwargs)
           ^^^^^^^^^^^^^^^^^^^^^^^^^^^^^^^^
  File "C:\Binson\Apps\Lib\site-packages\torch\nn\modules\module.py", line 1568, in _call_impl
    result = forward_call(*args, **kwargs)
             ^^^^^^^^^^^^^^^^^^^^^^^^^^^^^
  File "C:\Binson\Apps\Lib\site-packages\torch\nn\modules\conv.py", line 610, in forward
    return self._conv_forward(input, self.weight, self.bias)
           ^^^^^^^^^^^^^^^^^^^^^^^^^^^^^^^^^^^^^^^^^^^^^^^^^
  File "C:\Binson\Apps\Lib\site-packages\torch\nn\modules\conv.py", line 605, in _conv_forward
    return F.conv3d(
           ^^^^^^^^^
RuntimeError: Given groups=1, weight of size [128, 1, 3, 3, 3], expected input[1, 2, 2, 38, 51] to have 1 channels, but got 2 channels instead

The above exception was the direct cause of the following exception:

Traceback (most recent call last):
  File "c:\Binson\Cloud\OneDrive - University of Hertfordshire\ProjectWorkables\MscProjectRepo\smt_repo\testing model summary.py", line 260, in <module>
    summary(model,(2,38,51))
  File "C:\Binson\Apps\Lib\site-packages\torchsummary\torchsummary.py", line 143, in summary
    raise RuntimeError(
RuntimeError: Failed to run torchsummary. See above stack traces for more details. Executed layers up to: []
 
14:50:33 : ****************************** 
14:52:45 : ****************************** 
14:52:45 : Error occured Failed to run torchsummary. See above stack traces for more details. Executed layers up to: [] 
14:52:45 : Traceback (most recent call last):
  File "C:\Binson\Apps\Lib\site-packages\torchsummary\torchsummary.py", line 140, in summary
    _ = model.to(device)(*x, *args, **kwargs)  # type: ignore[misc]
        ^^^^^^^^^^^^^^^^^^^^^^^^^^^^^^^^^^^^^
  File "C:\Binson\Apps\Lib\site-packages\torch\nn\modules\module.py", line 1518, in _wrapped_call_impl
    return self._call_impl(*args, **kwargs)
           ^^^^^^^^^^^^^^^^^^^^^^^^^^^^^^^^
  File "C:\Binson\Apps\Lib\site-packages\torch\nn\modules\module.py", line 1527, in _call_impl
    return forward_call(*args, **kwargs)
           ^^^^^^^^^^^^^^^^^^^^^^^^^^^^^
  File "c:\Binson\Cloud\OneDrive - University of Hertfordshire\ProjectWorkables\MscProjectRepo\smt_repo\testing model summary.py", line 36, in forward
    x = self.pool(F.relu(self.conv1(x)))
                         ^^^^^^^^^^^^^
  File "C:\Binson\Apps\Lib\site-packages\torch\nn\modules\module.py", line 1518, in _wrapped_call_impl
    return self._call_impl(*args, **kwargs)
           ^^^^^^^^^^^^^^^^^^^^^^^^^^^^^^^^
  File "C:\Binson\Apps\Lib\site-packages\torch\nn\modules\module.py", line 1568, in _call_impl
    result = forward_call(*args, **kwargs)
             ^^^^^^^^^^^^^^^^^^^^^^^^^^^^^
  File "C:\Binson\Apps\Lib\site-packages\torch\nn\modules\conv.py", line 610, in forward
    return self._conv_forward(input, self.weight, self.bias)
           ^^^^^^^^^^^^^^^^^^^^^^^^^^^^^^^^^^^^^^^^^^^^^^^^^
  File "C:\Binson\Apps\Lib\site-packages\torch\nn\modules\conv.py", line 605, in _conv_forward
    return F.conv3d(
           ^^^^^^^^^
RuntimeError: Given groups=1, weight of size [128, 1, 3, 3, 3], expected input[2, 2, 1, 51, 38] to have 1 channels, but got 2 channels instead

The above exception was the direct cause of the following exception:

Traceback (most recent call last):
  File "c:\Binson\Cloud\OneDrive - University of Hertfordshire\ProjectWorkables\MscProjectRepo\smt_repo\testing model summary.py", line 260, in <module>
    summary(model,(2,1,51,38))
  File "C:\Binson\Apps\Lib\site-packages\torchsummary\torchsummary.py", line 143, in summary
    raise RuntimeError(
RuntimeError: Failed to run torchsummary. See above stack traces for more details. Executed layers up to: []
 
14:52:45 : ****************************** 
14:53:14 : ****************************** 
14:53:14 : Error occured Failed to run torchsummary. See above stack traces for more details. Executed layers up to: [Conv3d: 1-1] 
14:53:14 : Traceback (most recent call last):
  File "C:\Binson\Apps\Lib\site-packages\torchsummary\torchsummary.py", line 140, in summary
    _ = model.to(device)(*x, *args, **kwargs)  # type: ignore[misc]
        ^^^^^^^^^^^^^^^^^^^^^^^^^^^^^^^^^^^^^
  File "C:\Binson\Apps\Lib\site-packages\torch\nn\modules\module.py", line 1518, in _wrapped_call_impl
    return self._call_impl(*args, **kwargs)
           ^^^^^^^^^^^^^^^^^^^^^^^^^^^^^^^^
  File "C:\Binson\Apps\Lib\site-packages\torch\nn\modules\module.py", line 1527, in _call_impl
    return forward_call(*args, **kwargs)
           ^^^^^^^^^^^^^^^^^^^^^^^^^^^^^
  File "c:\Binson\Cloud\OneDrive - University of Hertfordshire\ProjectWorkables\MscProjectRepo\smt_repo\testing model summary.py", line 36, in forward
    x = self.pool(F.relu(self.conv1(x)))
        ^^^^^^^^^^^^^^^^^^^^^^^^^^^^^^^^
  File "C:\Binson\Apps\Lib\site-packages\torch\nn\modules\module.py", line 1518, in _wrapped_call_impl
    return self._call_impl(*args, **kwargs)
           ^^^^^^^^^^^^^^^^^^^^^^^^^^^^^^^^
  File "C:\Binson\Apps\Lib\site-packages\torch\nn\modules\module.py", line 1568, in _call_impl
    result = forward_call(*args, **kwargs)
             ^^^^^^^^^^^^^^^^^^^^^^^^^^^^^
  File "C:\Binson\Apps\Lib\site-packages\torch\nn\modules\pooling.py", line 244, in forward
    return F.max_pool3d(input, self.kernel_size, self.stride,
           ^^^^^^^^^^^^^^^^^^^^^^^^^^^^^^^^^^^^^^^^^^^^^^^^^^
  File "C:\Binson\Apps\Lib\site-packages\torch\_jit_internal.py", line 488, in fn
    return if_false(*args, **kwargs)
           ^^^^^^^^^^^^^^^^^^^^^^^^^
  File "C:\Binson\Apps\Lib\site-packages\torch\nn\functional.py", line 877, in _max_pool3d
    return torch.max_pool3d(input, kernel_size, stride, padding, dilation, ceil_mode)
           ^^^^^^^^^^^^^^^^^^^^^^^^^^^^^^^^^^^^^^^^^^^^^^^^^^^^^^^^^^^^^^^^^^^^^^^^^^
RuntimeError: Given input size: (128x1x51x38). Calculated output size: (128x0x25x19). Output size is too small

The above exception was the direct cause of the following exception:

Traceback (most recent call last):
  File "c:\Binson\Cloud\OneDrive - University of Hertfordshire\ProjectWorkables\MscProjectRepo\smt_repo\testing model summary.py", line 260, in <module>
    summary(model,(1,1,51,38))
  File "C:\Binson\Apps\Lib\site-packages\torchsummary\torchsummary.py", line 143, in summary
    raise RuntimeError(
RuntimeError: Failed to run torchsummary. See above stack traces for more details. Executed layers up to: [Conv3d: 1-1]
 
14:53:14 : ****************************** 
14:53:49 : ****************************** 
14:53:49 : Error occured Failed to run torchsummary. See above stack traces for more details. Executed layers up to: [] 
14:53:49 : Traceback (most recent call last):
  File "C:\Binson\Apps\Lib\site-packages\torchsummary\torchsummary.py", line 140, in summary
    _ = model.to(device)(*x, *args, **kwargs)  # type: ignore[misc]
        ^^^^^^^^^^^^^^^^^^^^^^^^^^^^^^^^^^^^^
  File "C:\Binson\Apps\Lib\site-packages\torch\nn\modules\module.py", line 1518, in _wrapped_call_impl
    return self._call_impl(*args, **kwargs)
           ^^^^^^^^^^^^^^^^^^^^^^^^^^^^^^^^
  File "C:\Binson\Apps\Lib\site-packages\torch\nn\modules\module.py", line 1527, in _call_impl
    return forward_call(*args, **kwargs)
           ^^^^^^^^^^^^^^^^^^^^^^^^^^^^^
  File "c:\Binson\Cloud\OneDrive - University of Hertfordshire\ProjectWorkables\MscProjectRepo\smt_repo\testing model summary.py", line 36, in forward
    x = self.pool(F.relu(self.conv1(x)))
                         ^^^^^^^^^^^^^
  File "C:\Binson\Apps\Lib\site-packages\torch\nn\modules\module.py", line 1518, in _wrapped_call_impl
    return self._call_impl(*args, **kwargs)
           ^^^^^^^^^^^^^^^^^^^^^^^^^^^^^^^^
  File "C:\Binson\Apps\Lib\site-packages\torch\nn\modules\module.py", line 1568, in _call_impl
    result = forward_call(*args, **kwargs)
             ^^^^^^^^^^^^^^^^^^^^^^^^^^^^^
  File "C:\Binson\Apps\Lib\site-packages\torch\nn\modules\conv.py", line 610, in forward
    return self._conv_forward(input, self.weight, self.bias)
           ^^^^^^^^^^^^^^^^^^^^^^^^^^^^^^^^^^^^^^^^^^^^^^^^^
  File "C:\Binson\Apps\Lib\site-packages\torch\nn\modules\conv.py", line 605, in _conv_forward
    return F.conv3d(
           ^^^^^^^^^
RuntimeError: Given groups=1, weight of size [128, 1, 3, 3, 3], expected input[2, 2, 1, 38, 51] to have 1 channels, but got 2 channels instead

The above exception was the direct cause of the following exception:

Traceback (most recent call last):
  File "c:\Binson\Cloud\OneDrive - University of Hertfordshire\ProjectWorkables\MscProjectRepo\smt_repo\testing model summary.py", line 260, in <module>
    summary(model,(2,1,38,51))
  File "C:\Binson\Apps\Lib\site-packages\torchsummary\torchsummary.py", line 143, in summary
    raise RuntimeError(
RuntimeError: Failed to run torchsummary. See above stack traces for more details. Executed layers up to: []
 
14:53:49 : ****************************** 
14:54:25 : ****************************** 
14:54:25 : Error occured Failed to run torchsummary. See above stack traces for more details. Executed layers up to: [Conv3d: 1-1, MaxPool3d: 1-2, Conv3d: 1-3] 
14:54:25 : Traceback (most recent call last):
  File "C:\Binson\Apps\Lib\site-packages\torchsummary\torchsummary.py", line 140, in summary
    _ = model.to(device)(*x, *args, **kwargs)  # type: ignore[misc]
        ^^^^^^^^^^^^^^^^^^^^^^^^^^^^^^^^^^^^^
  File "C:\Binson\Apps\Lib\site-packages\torch\nn\modules\module.py", line 1518, in _wrapped_call_impl
    return self._call_impl(*args, **kwargs)
           ^^^^^^^^^^^^^^^^^^^^^^^^^^^^^^^^
  File "C:\Binson\Apps\Lib\site-packages\torch\nn\modules\module.py", line 1527, in _call_impl
    return forward_call(*args, **kwargs)
           ^^^^^^^^^^^^^^^^^^^^^^^^^^^^^
  File "c:\Binson\Cloud\OneDrive - University of Hertfordshire\ProjectWorkables\MscProjectRepo\smt_repo\testing model summary.py", line 37, in forward
    x = self.pool(F.relu(self.conv2(x)))
        ^^^^^^^^^^^^^^^^^^^^^^^^^^^^^^^^
  File "C:\Binson\Apps\Lib\site-packages\torch\nn\modules\module.py", line 1518, in _wrapped_call_impl
    return self._call_impl(*args, **kwargs)
           ^^^^^^^^^^^^^^^^^^^^^^^^^^^^^^^^
  File "C:\Binson\Apps\Lib\site-packages\torch\nn\modules\module.py", line 1568, in _call_impl
    result = forward_call(*args, **kwargs)
             ^^^^^^^^^^^^^^^^^^^^^^^^^^^^^
  File "C:\Binson\Apps\Lib\site-packages\torch\nn\modules\pooling.py", line 244, in forward
    return F.max_pool3d(input, self.kernel_size, self.stride,
           ^^^^^^^^^^^^^^^^^^^^^^^^^^^^^^^^^^^^^^^^^^^^^^^^^^
  File "C:\Binson\Apps\Lib\site-packages\torch\_jit_internal.py", line 488, in fn
    return if_false(*args, **kwargs)
           ^^^^^^^^^^^^^^^^^^^^^^^^^
  File "C:\Binson\Apps\Lib\site-packages\torch\nn\functional.py", line 877, in _max_pool3d
    return torch.max_pool3d(input, kernel_size, stride, padding, dilation, ceil_mode)
           ^^^^^^^^^^^^^^^^^^^^^^^^^^^^^^^^^^^^^^^^^^^^^^^^^^^^^^^^^^^^^^^^^^^^^^^^^^
RuntimeError: Given input size: (128x1x19x25). Calculated output size: (128x0x9x12). Output size is too small

The above exception was the direct cause of the following exception:

Traceback (most recent call last):
  File "c:\Binson\Cloud\OneDrive - University of Hertfordshire\ProjectWorkables\MscProjectRepo\smt_repo\testing model summary.py", line 260, in <module>
    summary(model,(1,2,38,51))
  File "C:\Binson\Apps\Lib\site-packages\torchsummary\torchsummary.py", line 143, in summary
    raise RuntimeError(
RuntimeError: Failed to run torchsummary. See above stack traces for more details. Executed layers up to: [Conv3d: 1-1, MaxPool3d: 1-2, Conv3d: 1-3]
 
14:54:25 : ****************************** 
14:54:42 : ****************************** 
14:54:42 : Error occured Failed to run torchsummary. See above stack traces for more details. Executed layers up to: [Conv3d: 1-1, MaxPool3d: 1-2, Conv3d: 1-3] 
14:54:42 : Traceback (most recent call last):
  File "C:\Binson\Apps\Lib\site-packages\torchsummary\torchsummary.py", line 140, in summary
    _ = model.to(device)(*x, *args, **kwargs)  # type: ignore[misc]
        ^^^^^^^^^^^^^^^^^^^^^^^^^^^^^^^^^^^^^
  File "C:\Binson\Apps\Lib\site-packages\torch\nn\modules\module.py", line 1518, in _wrapped_call_impl
    return self._call_impl(*args, **kwargs)
           ^^^^^^^^^^^^^^^^^^^^^^^^^^^^^^^^
  File "C:\Binson\Apps\Lib\site-packages\torch\nn\modules\module.py", line 1527, in _call_impl
    return forward_call(*args, **kwargs)
           ^^^^^^^^^^^^^^^^^^^^^^^^^^^^^
  File "c:\Binson\Cloud\OneDrive - University of Hertfordshire\ProjectWorkables\MscProjectRepo\smt_repo\testing model summary.py", line 37, in forward
    x = self.pool(F.relu(self.conv2(x)))
        ^^^^^^^^^^^^^^^^^^^^^^^^^^^^^^^^
  File "C:\Binson\Apps\Lib\site-packages\torch\nn\modules\module.py", line 1518, in _wrapped_call_impl
    return self._call_impl(*args, **kwargs)
           ^^^^^^^^^^^^^^^^^^^^^^^^^^^^^^^^
  File "C:\Binson\Apps\Lib\site-packages\torch\nn\modules\module.py", line 1568, in _call_impl
    result = forward_call(*args, **kwargs)
             ^^^^^^^^^^^^^^^^^^^^^^^^^^^^^
  File "C:\Binson\Apps\Lib\site-packages\torch\nn\modules\pooling.py", line 244, in forward
    return F.max_pool3d(input, self.kernel_size, self.stride,
           ^^^^^^^^^^^^^^^^^^^^^^^^^^^^^^^^^^^^^^^^^^^^^^^^^^
  File "C:\Binson\Apps\Lib\site-packages\torch\_jit_internal.py", line 488, in fn
    return if_false(*args, **kwargs)
           ^^^^^^^^^^^^^^^^^^^^^^^^^
  File "C:\Binson\Apps\Lib\site-packages\torch\nn\functional.py", line 877, in _max_pool3d
    return torch.max_pool3d(input, kernel_size, stride, padding, dilation, ceil_mode)
           ^^^^^^^^^^^^^^^^^^^^^^^^^^^^^^^^^^^^^^^^^^^^^^^^^^^^^^^^^^^^^^^^^^^^^^^^^^
RuntimeError: Given input size: (128x1x19x25). Calculated output size: (128x0x9x12). Output size is too small

The above exception was the direct cause of the following exception:

Traceback (most recent call last):
  File "c:\Binson\Cloud\OneDrive - University of Hertfordshire\ProjectWorkables\MscProjectRepo\smt_repo\testing model summary.py", line 260, in <module>
    summary(model,(1,3,38,51))
  File "C:\Binson\Apps\Lib\site-packages\torchsummary\torchsummary.py", line 143, in summary
    raise RuntimeError(
RuntimeError: Failed to run torchsummary. See above stack traces for more details. Executed layers up to: [Conv3d: 1-1, MaxPool3d: 1-2, Conv3d: 1-3]
 
14:54:42 : ****************************** 
14:55:01 : ****************************** 
14:55:01 : Error occured Failed to run torchsummary. See above stack traces for more details. Executed layers up to: [] 
14:55:01 : Traceback (most recent call last):
  File "C:\Binson\Apps\Lib\site-packages\torchsummary\torchsummary.py", line 140, in summary
    _ = model.to(device)(*x, *args, **kwargs)  # type: ignore[misc]
        ^^^^^^^^^^^^^^^^^^^^^^^^^^^^^^^^^^^^^
  File "C:\Binson\Apps\Lib\site-packages\torch\nn\modules\module.py", line 1518, in _wrapped_call_impl
    return self._call_impl(*args, **kwargs)
           ^^^^^^^^^^^^^^^^^^^^^^^^^^^^^^^^
  File "C:\Binson\Apps\Lib\site-packages\torch\nn\modules\module.py", line 1527, in _call_impl
    return forward_call(*args, **kwargs)
           ^^^^^^^^^^^^^^^^^^^^^^^^^^^^^
  File "c:\Binson\Cloud\OneDrive - University of Hertfordshire\ProjectWorkables\MscProjectRepo\smt_repo\testing model summary.py", line 36, in forward
    x = self.pool(F.relu(self.conv1(x)))
                         ^^^^^^^^^^^^^
  File "C:\Binson\Apps\Lib\site-packages\torch\nn\modules\module.py", line 1518, in _wrapped_call_impl
    return self._call_impl(*args, **kwargs)
           ^^^^^^^^^^^^^^^^^^^^^^^^^^^^^^^^
  File "C:\Binson\Apps\Lib\site-packages\torch\nn\modules\module.py", line 1568, in _call_impl
    result = forward_call(*args, **kwargs)
             ^^^^^^^^^^^^^^^^^^^^^^^^^^^^^
  File "C:\Binson\Apps\Lib\site-packages\torch\nn\modules\conv.py", line 610, in forward
    return self._conv_forward(input, self.weight, self.bias)
           ^^^^^^^^^^^^^^^^^^^^^^^^^^^^^^^^^^^^^^^^^^^^^^^^^
  File "C:\Binson\Apps\Lib\site-packages\torch\nn\modules\conv.py", line 605, in _conv_forward
    return F.conv3d(
           ^^^^^^^^^
RuntimeError: Given groups=1, weight of size [128, 1, 3, 3, 3], expected input[2, 2, 3, 38, 51] to have 1 channels, but got 2 channels instead

The above exception was the direct cause of the following exception:

Traceback (most recent call last):
  File "c:\Binson\Cloud\OneDrive - University of Hertfordshire\ProjectWorkables\MscProjectRepo\smt_repo\testing model summary.py", line 260, in <module>
    summary(model,(2,3,38,51))
  File "C:\Binson\Apps\Lib\site-packages\torchsummary\torchsummary.py", line 143, in summary
    raise RuntimeError(
RuntimeError: Failed to run torchsummary. See above stack traces for more details. Executed layers up to: []
 
14:55:01 : ****************************** 
14:55:33 : ****************************** 
14:55:33 : Error occured Failed to run torchsummary. See above stack traces for more details. Executed layers up to: [Conv3d: 1-1, MaxPool3d: 1-2, Conv3d: 1-3] 
14:55:33 : Traceback (most recent call last):
  File "C:\Binson\Apps\Lib\site-packages\torchsummary\torchsummary.py", line 140, in summary
    _ = model.to(device)(*x, *args, **kwargs)  # type: ignore[misc]
        ^^^^^^^^^^^^^^^^^^^^^^^^^^^^^^^^^^^^^
  File "C:\Binson\Apps\Lib\site-packages\torch\nn\modules\module.py", line 1518, in _wrapped_call_impl
    return self._call_impl(*args, **kwargs)
           ^^^^^^^^^^^^^^^^^^^^^^^^^^^^^^^^
  File "C:\Binson\Apps\Lib\site-packages\torch\nn\modules\module.py", line 1527, in _call_impl
    return forward_call(*args, **kwargs)
           ^^^^^^^^^^^^^^^^^^^^^^^^^^^^^
  File "c:\Binson\Cloud\OneDrive - University of Hertfordshire\ProjectWorkables\MscProjectRepo\smt_repo\testing model summary.py", line 37, in forward
    x = self.pool(F.relu(self.conv2(x)))
        ^^^^^^^^^^^^^^^^^^^^^^^^^^^^^^^^
  File "C:\Binson\Apps\Lib\site-packages\torch\nn\modules\module.py", line 1518, in _wrapped_call_impl
    return self._call_impl(*args, **kwargs)
           ^^^^^^^^^^^^^^^^^^^^^^^^^^^^^^^^
  File "C:\Binson\Apps\Lib\site-packages\torch\nn\modules\module.py", line 1568, in _call_impl
    result = forward_call(*args, **kwargs)
             ^^^^^^^^^^^^^^^^^^^^^^^^^^^^^
  File "C:\Binson\Apps\Lib\site-packages\torch\nn\modules\pooling.py", line 244, in forward
    return F.max_pool3d(input, self.kernel_size, self.stride,
           ^^^^^^^^^^^^^^^^^^^^^^^^^^^^^^^^^^^^^^^^^^^^^^^^^^
  File "C:\Binson\Apps\Lib\site-packages\torch\_jit_internal.py", line 488, in fn
    return if_false(*args, **kwargs)
           ^^^^^^^^^^^^^^^^^^^^^^^^^
  File "C:\Binson\Apps\Lib\site-packages\torch\nn\functional.py", line 877, in _max_pool3d
    return torch.max_pool3d(input, kernel_size, stride, padding, dilation, ceil_mode)
           ^^^^^^^^^^^^^^^^^^^^^^^^^^^^^^^^^^^^^^^^^^^^^^^^^^^^^^^^^^^^^^^^^^^^^^^^^^
RuntimeError: Given input size: (128x1x19x25). Calculated output size: (128x0x9x12). Output size is too small

The above exception was the direct cause of the following exception:

Traceback (most recent call last):
  File "c:\Binson\Cloud\OneDrive - University of Hertfordshire\ProjectWorkables\MscProjectRepo\smt_repo\testing model summary.py", line 260, in <module>
    summary(model,(1,3,38,51))
  File "C:\Binson\Apps\Lib\site-packages\torchsummary\torchsummary.py", line 143, in summary
    raise RuntimeError(
RuntimeError: Failed to run torchsummary. See above stack traces for more details. Executed layers up to: [Conv3d: 1-1, MaxPool3d: 1-2, Conv3d: 1-3]
 
14:55:33 : ****************************** 
14:56:05 : ****************************** 
14:56:05 : Error occured Failed to run torchsummary. See above stack traces for more details. Executed layers up to: [Conv3d: 1-1, MaxPool3d: 1-2, Conv3d: 1-3] 
14:56:05 : Traceback (most recent call last):
  File "C:\Binson\Apps\Lib\site-packages\torchsummary\torchsummary.py", line 140, in summary
    _ = model.to(device)(*x, *args, **kwargs)  # type: ignore[misc]
        ^^^^^^^^^^^^^^^^^^^^^^^^^^^^^^^^^^^^^
  File "C:\Binson\Apps\Lib\site-packages\torch\nn\modules\module.py", line 1518, in _wrapped_call_impl
    return self._call_impl(*args, **kwargs)
           ^^^^^^^^^^^^^^^^^^^^^^^^^^^^^^^^
  File "C:\Binson\Apps\Lib\site-packages\torch\nn\modules\module.py", line 1527, in _call_impl
    return forward_call(*args, **kwargs)
           ^^^^^^^^^^^^^^^^^^^^^^^^^^^^^
  File "c:\Binson\Cloud\OneDrive - University of Hertfordshire\ProjectWorkables\MscProjectRepo\smt_repo\testing model summary.py", line 37, in forward
    x = self.pool(F.relu(self.conv2(x)))
        ^^^^^^^^^^^^^^^^^^^^^^^^^^^^^^^^
  File "C:\Binson\Apps\Lib\site-packages\torch\nn\modules\module.py", line 1518, in _wrapped_call_impl
    return self._call_impl(*args, **kwargs)
           ^^^^^^^^^^^^^^^^^^^^^^^^^^^^^^^^
  File "C:\Binson\Apps\Lib\site-packages\torch\nn\modules\module.py", line 1568, in _call_impl
    result = forward_call(*args, **kwargs)
             ^^^^^^^^^^^^^^^^^^^^^^^^^^^^^
  File "C:\Binson\Apps\Lib\site-packages\torch\nn\modules\pooling.py", line 244, in forward
    return F.max_pool3d(input, self.kernel_size, self.stride,
           ^^^^^^^^^^^^^^^^^^^^^^^^^^^^^^^^^^^^^^^^^^^^^^^^^^
  File "C:\Binson\Apps\Lib\site-packages\torch\_jit_internal.py", line 488, in fn
    return if_false(*args, **kwargs)
           ^^^^^^^^^^^^^^^^^^^^^^^^^
  File "C:\Binson\Apps\Lib\site-packages\torch\nn\functional.py", line 877, in _max_pool3d
    return torch.max_pool3d(input, kernel_size, stride, padding, dilation, ceil_mode)
           ^^^^^^^^^^^^^^^^^^^^^^^^^^^^^^^^^^^^^^^^^^^^^^^^^^^^^^^^^^^^^^^^^^^^^^^^^^
RuntimeError: Given input size: (128x1x25x19). Calculated output size: (128x0x12x9). Output size is too small

The above exception was the direct cause of the following exception:

Traceback (most recent call last):
  File "c:\Binson\Cloud\OneDrive - University of Hertfordshire\ProjectWorkables\MscProjectRepo\smt_repo\testing model summary.py", line 260, in <module>
    summary(model,(1,3,51,38))
  File "C:\Binson\Apps\Lib\site-packages\torchsummary\torchsummary.py", line 143, in summary
    raise RuntimeError(
RuntimeError: Failed to run torchsummary. See above stack traces for more details. Executed layers up to: [Conv3d: 1-1, MaxPool3d: 1-2, Conv3d: 1-3]
 
14:56:05 : ****************************** 
14:56:28 : ****************************** 
14:56:28 : Error occured Failed to run torchsummary. See above stack traces for more details. Executed layers up to: [] 
14:56:28 : Traceback (most recent call last):
  File "C:\Binson\Apps\Lib\site-packages\torchsummary\torchsummary.py", line 140, in summary
    _ = model.to(device)(*x, *args, **kwargs)  # type: ignore[misc]
        ^^^^^^^^^^^^^^^^^^^^^^^^^^^^^^^^^^^^^
  File "C:\Binson\Apps\Lib\site-packages\torch\nn\modules\module.py", line 1518, in _wrapped_call_impl
    return self._call_impl(*args, **kwargs)
           ^^^^^^^^^^^^^^^^^^^^^^^^^^^^^^^^
  File "C:\Binson\Apps\Lib\site-packages\torch\nn\modules\module.py", line 1527, in _call_impl
    return forward_call(*args, **kwargs)
           ^^^^^^^^^^^^^^^^^^^^^^^^^^^^^
  File "c:\Binson\Cloud\OneDrive - University of Hertfordshire\ProjectWorkables\MscProjectRepo\smt_repo\testing model summary.py", line 36, in forward
    x = self.pool(F.relu(self.conv1(x)))
                         ^^^^^^^^^^^^^
  File "C:\Binson\Apps\Lib\site-packages\torch\nn\modules\module.py", line 1518, in _wrapped_call_impl
    return self._call_impl(*args, **kwargs)
           ^^^^^^^^^^^^^^^^^^^^^^^^^^^^^^^^
  File "C:\Binson\Apps\Lib\site-packages\torch\nn\modules\module.py", line 1568, in _call_impl
    result = forward_call(*args, **kwargs)
             ^^^^^^^^^^^^^^^^^^^^^^^^^^^^^
  File "C:\Binson\Apps\Lib\site-packages\torch\nn\modules\conv.py", line 610, in forward
    return self._conv_forward(input, self.weight, self.bias)
           ^^^^^^^^^^^^^^^^^^^^^^^^^^^^^^^^^^^^^^^^^^^^^^^^^
  File "C:\Binson\Apps\Lib\site-packages\torch\nn\modules\conv.py", line 605, in _conv_forward
    return F.conv3d(
           ^^^^^^^^^
RuntimeError: Given groups=1, weight of size [128, 1, 3, 3, 3], expected input[2, 2, 3, 51, 38] to have 1 channels, but got 2 channels instead

The above exception was the direct cause of the following exception:

Traceback (most recent call last):
  File "c:\Binson\Cloud\OneDrive - University of Hertfordshire\ProjectWorkables\MscProjectRepo\smt_repo\testing model summary.py", line 260, in <module>
    summary(model,(2,3,51,38))
  File "C:\Binson\Apps\Lib\site-packages\torchsummary\torchsummary.py", line 143, in summary
    raise RuntimeError(
RuntimeError: Failed to run torchsummary. See above stack traces for more details. Executed layers up to: []
 
14:56:28 : ****************************** 
14:56:49 : ****************************** 
14:56:49 : Error occured Failed to run torchsummary. See above stack traces for more details. Executed layers up to: [Conv3d: 1-1, MaxPool3d: 1-2, Conv3d: 1-3] 
14:56:49 : Traceback (most recent call last):
  File "C:\Binson\Apps\Lib\site-packages\torchsummary\torchsummary.py", line 140, in summary
    _ = model.to(device)(*x, *args, **kwargs)  # type: ignore[misc]
        ^^^^^^^^^^^^^^^^^^^^^^^^^^^^^^^^^^^^^
  File "C:\Binson\Apps\Lib\site-packages\torch\nn\modules\module.py", line 1518, in _wrapped_call_impl
    return self._call_impl(*args, **kwargs)
           ^^^^^^^^^^^^^^^^^^^^^^^^^^^^^^^^
  File "C:\Binson\Apps\Lib\site-packages\torch\nn\modules\module.py", line 1527, in _call_impl
    return forward_call(*args, **kwargs)
           ^^^^^^^^^^^^^^^^^^^^^^^^^^^^^
  File "c:\Binson\Cloud\OneDrive - University of Hertfordshire\ProjectWorkables\MscProjectRepo\smt_repo\testing model summary.py", line 37, in forward
    x = self.pool(F.relu(self.conv2(x)))
        ^^^^^^^^^^^^^^^^^^^^^^^^^^^^^^^^
  File "C:\Binson\Apps\Lib\site-packages\torch\nn\modules\module.py", line 1518, in _wrapped_call_impl
    return self._call_impl(*args, **kwargs)
           ^^^^^^^^^^^^^^^^^^^^^^^^^^^^^^^^
  File "C:\Binson\Apps\Lib\site-packages\torch\nn\modules\module.py", line 1568, in _call_impl
    result = forward_call(*args, **kwargs)
             ^^^^^^^^^^^^^^^^^^^^^^^^^^^^^
  File "C:\Binson\Apps\Lib\site-packages\torch\nn\modules\pooling.py", line 244, in forward
    return F.max_pool3d(input, self.kernel_size, self.stride,
           ^^^^^^^^^^^^^^^^^^^^^^^^^^^^^^^^^^^^^^^^^^^^^^^^^^
  File "C:\Binson\Apps\Lib\site-packages\torch\_jit_internal.py", line 488, in fn
    return if_false(*args, **kwargs)
           ^^^^^^^^^^^^^^^^^^^^^^^^^
  File "C:\Binson\Apps\Lib\site-packages\torch\nn\functional.py", line 877, in _max_pool3d
    return torch.max_pool3d(input, kernel_size, stride, padding, dilation, ceil_mode)
           ^^^^^^^^^^^^^^^^^^^^^^^^^^^^^^^^^^^^^^^^^^^^^^^^^^^^^^^^^^^^^^^^^^^^^^^^^^
RuntimeError: Given input size: (128x1x25x19). Calculated output size: (128x0x12x9). Output size is too small

The above exception was the direct cause of the following exception:

Traceback (most recent call last):
  File "c:\Binson\Cloud\OneDrive - University of Hertfordshire\ProjectWorkables\MscProjectRepo\smt_repo\testing model summary.py", line 260, in <module>
    summary(model,(1,3,51,38))
  File "C:\Binson\Apps\Lib\site-packages\torchsummary\torchsummary.py", line 143, in summary
    raise RuntimeError(
RuntimeError: Failed to run torchsummary. See above stack traces for more details. Executed layers up to: [Conv3d: 1-1, MaxPool3d: 1-2, Conv3d: 1-3]
 
14:56:49 : ****************************** 
14:57:04 : ****************************** 
14:57:04 : Error occured Failed to run torchsummary. See above stack traces for more details. Executed layers up to: [Conv3d: 1-1] 
14:57:04 : Traceback (most recent call last):
  File "C:\Binson\Apps\Lib\site-packages\torchsummary\torchsummary.py", line 140, in summary
    _ = model.to(device)(*x, *args, **kwargs)  # type: ignore[misc]
        ^^^^^^^^^^^^^^^^^^^^^^^^^^^^^^^^^^^^^
  File "C:\Binson\Apps\Lib\site-packages\torch\nn\modules\module.py", line 1518, in _wrapped_call_impl
    return self._call_impl(*args, **kwargs)
           ^^^^^^^^^^^^^^^^^^^^^^^^^^^^^^^^
  File "C:\Binson\Apps\Lib\site-packages\torch\nn\modules\module.py", line 1527, in _call_impl
    return forward_call(*args, **kwargs)
           ^^^^^^^^^^^^^^^^^^^^^^^^^^^^^
  File "c:\Binson\Cloud\OneDrive - University of Hertfordshire\ProjectWorkables\MscProjectRepo\smt_repo\testing model summary.py", line 36, in forward
    x = self.pool(F.relu(self.conv1(x)))
        ^^^^^^^^^^^^^^^^^^^^^^^^^^^^^^^^
  File "C:\Binson\Apps\Lib\site-packages\torch\nn\modules\module.py", line 1518, in _wrapped_call_impl
    return self._call_impl(*args, **kwargs)
           ^^^^^^^^^^^^^^^^^^^^^^^^^^^^^^^^
  File "C:\Binson\Apps\Lib\site-packages\torch\nn\modules\module.py", line 1568, in _call_impl
    result = forward_call(*args, **kwargs)
             ^^^^^^^^^^^^^^^^^^^^^^^^^^^^^
  File "C:\Binson\Apps\Lib\site-packages\torch\nn\modules\pooling.py", line 244, in forward
    return F.max_pool3d(input, self.kernel_size, self.stride,
           ^^^^^^^^^^^^^^^^^^^^^^^^^^^^^^^^^^^^^^^^^^^^^^^^^^
  File "C:\Binson\Apps\Lib\site-packages\torch\_jit_internal.py", line 488, in fn
    return if_false(*args, **kwargs)
           ^^^^^^^^^^^^^^^^^^^^^^^^^
  File "C:\Binson\Apps\Lib\site-packages\torch\nn\functional.py", line 877, in _max_pool3d
    return torch.max_pool3d(input, kernel_size, stride, padding, dilation, ceil_mode)
           ^^^^^^^^^^^^^^^^^^^^^^^^^^^^^^^^^^^^^^^^^^^^^^^^^^^^^^^^^^^^^^^^^^^^^^^^^^
RuntimeError: Given input size: (128x1x51x38). Calculated output size: (128x0x25x19). Output size is too small

The above exception was the direct cause of the following exception:

Traceback (most recent call last):
  File "c:\Binson\Cloud\OneDrive - University of Hertfordshire\ProjectWorkables\MscProjectRepo\smt_repo\testing model summary.py", line 260, in <module>
    summary(model,(1,1,51,38))
  File "C:\Binson\Apps\Lib\site-packages\torchsummary\torchsummary.py", line 143, in summary
    raise RuntimeError(
RuntimeError: Failed to run torchsummary. See above stack traces for more details. Executed layers up to: [Conv3d: 1-1]
 
14:57:04 : ****************************** 
